<!DOCTYPE html>
<html>
<head>
    <meta charset="UTF-8">
    <meta name="viewport" content="width=device-width, initial-scale=1.0">
    <meta http-equiv="X-UA-Compatible" content="ie=edge">
    <title>then和catch改变状态</title>
</head>
<body>
    鼠标右击查看源码
</body>
<script>
// then正常返回resolved，里面有报错则返回rejected
const p1 = Promise.resolve().then(()=> {
    return 100
})
console.log("p1", p1);  // resolve状态 触发后续then的回调
// 因为p1是resolve状态
p1.then(()=> {
    console.log('p3 2333');  // 触发后续then的回调
})

const p2 = Promise.resolve().then(()=> {
    throw new Error('then error p2')
})
console.log("p2", p2);  // rejected状态 触发后续catch的回调
// 因为p1是rejected状态
p2.then(()=> {
    console.log('24444');  // 无法触发
}).catch(err=> {
    console.log('err', err);  // 可以触发
})

// catch正常返回resolved，里面有报错则返回rejected
const p3 = Promise.reject('my error').catch(err=> {
    console.log('err', err);
});
console.log("p3", p3);  // 此时的状态是resolved - 重点！
// 因为p3是resolve状态
p3.then(()=> {
    console.log('p3 2333');  // 触发后续then的回调
})

const p4 = Promise.reject('my error').catch(err=> {
    throw new Error('then error p4')
});
console.log("p4", p4);  // 此时的状态是reject
// 因为p4是rejected状态
p4.then(()=> {
    console.log('24444');  // 无法触发
}).catch(err=> {
    console.log('err', err);  // 可以触发
})
// p4.catch()里面没有报错，即它的promise状态也是resolved

// 不管是then还是catch，只要是正常返回，promise状态就都是resolved，只要报错，promise状态就都是rejected
</script>
</html>